2020-01-06 05:00:00 connectionpool.py [line:225] DEBUG: Starting new HTTP connection (1): 202.104.113.35:53281
2020-01-06 05:00:10 httpbin_validator.py [line:82] ERROR: HTTPConnectionPool(host='202.104.113.35', port=53281): Read timed out. (read timeout=10)
Traceback (most recent call last):
  File "D:\ziyou\Anaconda3\lib\site-packages\urllib3\connectionpool.py", line 421, in _make_request
    six.raise_from(e, None)
  File "<string>", line 3, in raise_from
  File "D:\ziyou\Anaconda3\lib\site-packages\urllib3\connectionpool.py", line 416, in _make_request
    httplib_response = conn.getresponse()
  File "D:\ziyou\Anaconda3\lib\http\client.py", line 1344, in getresponse
    response.begin()
  File "D:\ziyou\Anaconda3\lib\http\client.py", line 306, in begin
    version, status, reason = self._read_status()
  File "D:\ziyou\Anaconda3\lib\http\client.py", line 267, in _read_status
    line = str(self.fp.readline(_MAXLINE + 1), "iso-8859-1")
  File "D:\ziyou\Anaconda3\lib\socket.py", line 589, in readinto
    return self._sock.recv_into(b)
socket.timeout: timed out

During handling of the above exception, another exception occurred:

Traceback (most recent call last):
  File "D:\ziyou\Anaconda3\lib\site-packages\requests\adapters.py", line 449, in send
    timeout=timeout
  File "D:\ziyou\Anaconda3\lib\site-packages\urllib3\connectionpool.py", line 720, in urlopen
    method, url, error=e, _pool=self, _stacktrace=sys.exc_info()[2]
  File "D:\ziyou\Anaconda3\lib\site-packages\urllib3\util\retry.py", line 400, in increment
    raise six.reraise(type(error), error, _stacktrace)
  File "D:\ziyou\Anaconda3\lib\site-packages\urllib3\packages\six.py", line 735, in reraise
    raise value
  File "D:\ziyou\Anaconda3\lib\site-packages\urllib3\connectionpool.py", line 672, in urlopen
    chunked=chunked,
  File "D:\ziyou\Anaconda3\lib\site-packages\urllib3\connectionpool.py", line 423, in _make_request
    self._raise_timeout(err=e, url=url, timeout_value=read_timeout)
  File "D:\ziyou\Anaconda3\lib\site-packages\urllib3\connectionpool.py", line 331, in _raise_timeout
    self, url, "Read timed out. (read timeout=%s)" % timeout_value
urllib3.exceptions.ReadTimeoutError: HTTPConnectionPool(host='202.104.113.35', port=53281): Read timed out. (read timeout=10)

During handling of the above exception, another exception occurred:

Traceback (most recent call last):
  File "D:/ziyou/Anaconda3/envs/lzy/IPProxyPool/core/proxy_validate/httpbin_validator.py", line 60, in __check_http_proxies
    response = requests.get(test_url,headers=get_request_headers(),proxies=proxies,timeout=TEST_TIMEOUT)
  File "D:\ziyou\Anaconda3\lib\site-packages\requests\api.py", line 75, in get
    return request('get', url, params=params, **kwargs)
  File "D:\ziyou\Anaconda3\lib\site-packages\requests\api.py", line 60, in request
    return session.request(method=method, url=url, **kwargs)
  File "D:\ziyou\Anaconda3\lib\site-packages\requests\sessions.py", line 533, in request
    resp = self.send(prep, **send_kwargs)
  File "D:\ziyou\Anaconda3\lib\site-packages\requests\sessions.py", line 646, in send
    r = adapter.send(request, **kwargs)
  File "D:\ziyou\Anaconda3\lib\site-packages\requests\adapters.py", line 529, in send
    raise ReadTimeout(e, request=request)
requests.exceptions.ReadTimeout: HTTPConnectionPool(host='202.104.113.35', port=53281): Read timed out. (read timeout=10)
2020-01-06 05:00:10 connectionpool.py [line:959] DEBUG: Starting new HTTPS connection (1): httpbin.org:443
2020-01-06 05:00:20 httpbin_validator.py [line:82] ERROR: HTTPSConnectionPool(host='httpbin.org', port=443): Max retries exceeded with url: /get (Caused by ConnectTimeoutError(<urllib3.connection.VerifiedHTTPSConnection object at 0x000001A59C60F9C8>, 'Connection to 202.104.113.35 timed out. (connect timeout=10)'))
Traceback (most recent call last):
  File "D:\ziyou\Anaconda3\lib\site-packages\urllib3\connection.py", line 157, in _new_conn
    (self._dns_host, self.port), self.timeout, **extra_kw
  File "D:\ziyou\Anaconda3\lib\site-packages\urllib3\util\connection.py", line 84, in create_connection
    raise err
  File "D:\ziyou\Anaconda3\lib\site-packages\urllib3\util\connection.py", line 74, in create_connection
    sock.connect(sa)
socket.timeout: timed out

During handling of the above exception, another exception occurred:

Traceback (most recent call last):
  File "D:\ziyou\Anaconda3\lib\site-packages\urllib3\connectionpool.py", line 662, in urlopen
    self._prepare_proxy(conn)
  File "D:\ziyou\Anaconda3\lib\site-packages\urllib3\connectionpool.py", line 948, in _prepare_proxy
    conn.connect()
  File "D:\ziyou\Anaconda3\lib\site-packages\urllib3\connection.py", line 334, in connect
    conn = self._new_conn()
  File "D:\ziyou\Anaconda3\lib\site-packages\urllib3\connection.py", line 164, in _new_conn
    % (self.host, self.timeout),
urllib3.exceptions.ConnectTimeoutError: (<urllib3.connection.VerifiedHTTPSConnection object at 0x000001A59C60F9C8>, 'Connection to 202.104.113.35 timed out. (connect timeout=10)')

During handling of the above exception, another exception occurred:

Traceback (most recent call last):
  File "D:\ziyou\Anaconda3\lib\site-packages\requests\adapters.py", line 449, in send
    timeout=timeout
  File "D:\ziyou\Anaconda3\lib\site-packages\urllib3\connectionpool.py", line 720, in urlopen
    method, url, error=e, _pool=self, _stacktrace=sys.exc_info()[2]
  File "D:\ziyou\Anaconda3\lib\site-packages\urllib3\util\retry.py", line 436, in increment
    raise MaxRetryError(_pool, url, error or ResponseError(cause))
urllib3.exceptions.MaxRetryError: HTTPSConnectionPool(host='httpbin.org', port=443): Max retries exceeded with url: /get (Caused by ConnectTimeoutError(<urllib3.connection.VerifiedHTTPSConnection object at 0x000001A59C60F9C8>, 'Connection to 202.104.113.35 timed out. (connect timeout=10)'))

During handling of the above exception, another exception occurred:

Traceback (most recent call last):
  File "D:/ziyou/Anaconda3/envs/lzy/IPProxyPool/core/proxy_validate/httpbin_validator.py", line 60, in __check_http_proxies
    response = requests.get(test_url,headers=get_request_headers(),proxies=proxies,timeout=TEST_TIMEOUT)
  File "D:\ziyou\Anaconda3\lib\site-packages\requests\api.py", line 75, in get
    return request('get', url, params=params, **kwargs)
  File "D:\ziyou\Anaconda3\lib\site-packages\requests\api.py", line 60, in request
    return session.request(method=method, url=url, **kwargs)
  File "D:\ziyou\Anaconda3\lib\site-packages\requests\sessions.py", line 533, in request
    resp = self.send(prep, **send_kwargs)
  File "D:\ziyou\Anaconda3\lib\site-packages\requests\sessions.py", line 646, in send
    r = adapter.send(request, **kwargs)
  File "D:\ziyou\Anaconda3\lib\site-packages\requests\adapters.py", line 504, in send
    raise ConnectTimeout(e, request=request)
requests.exceptions.ConnectTimeout: HTTPSConnectionPool(host='httpbin.org', port=443): Max retries exceeded with url: /get (Caused by ConnectTimeoutError(<urllib3.connection.VerifiedHTTPSConnection object at 0x000001A59C60F9C8>, 'Connection to 202.104.113.35 timed out. (connect timeout=10)'))
2020-01-06 05:06:33 connectionpool.py [line:225] DEBUG: Starting new HTTP connection (1): 202.104.113.35:53281
2020-01-06 05:06:43 connectionpool.py [line:959] DEBUG: Starting new HTTPS connection (1): httpbin.org:443
2020-01-06 05:08:15 connectionpool.py [line:225] DEBUG: Starting new HTTP connection (1): 58.212.40.172:9999
2020-01-06 05:08:15 connectionpool.py [line:437] DEBUG: http://58.212.40.172:9999 "GET http://httpbin.org/get HTTP/1.1" 200 351
2020-01-06 05:08:15 connectionpool.py [line:959] DEBUG: Starting new HTTPS connection (1): httpbin.org:443
2020-01-06 05:08:17 connectionpool.py [line:437] DEBUG: https://httpbin.org:443 "GET /get HTTP/1.1" 200 265
2020-01-06 05:15:48 connectionpool.py [line:225] DEBUG: Starting new HTTP connection (1): 112.85.125.186:9999
2020-01-06 05:15:56 connectionpool.py [line:437] DEBUG: http://112.85.125.186:9999 "GET http://httpbin.org/get HTTP/1.1" 200 291
2020-01-06 05:15:57 connectionpool.py [line:959] DEBUG: Starting new HTTPS connection (1): httpbin.org:443
2020-01-06 05:16:01 connectionpool.py [line:437] DEBUG: https://httpbin.org:443 "GET /get HTTP/1.1" 200 311
2020-01-08 09:59:56 connectionpool.py [line:225] DEBUG: Starting new HTTP connection (1): 112.85.125.186:9999
2020-01-08 09:59:58 connectionpool.py [line:959] DEBUG: Starting new HTTPS connection (1): httpbin.org:443
2020-01-08 10:09:45 connectionpool.py [line:225] DEBUG: Starting new HTTP connection (1): 223.199.28.160:9999
2020-01-08 10:09:47 connectionpool.py [line:959] DEBUG: Starting new HTTPS connection (1): httpbin.org:443
2020-01-08 10:10:40 connectionpool.py [line:225] DEBUG: Starting new HTTP connection (1): 223.199.19.109:9999
2020-01-08 10:10:50 connectionpool.py [line:959] DEBUG: Starting new HTTPS connection (1): httpbin.org:443
2020-01-08 10:11:32 connectionpool.py [line:225] DEBUG: Starting new HTTP connection (1): 218.14.109.42:44942
2020-01-08 10:11:34 connectionpool.py [line:959] DEBUG: Starting new HTTPS connection (1): httpbin.org:443
2020-01-08 10:20:43 connectionpool.py [line:225] DEBUG: Starting new HTTP connection (1): 218.14.109.42:44942
2020-01-08 10:20:45 connectionpool.py [line:959] DEBUG: Starting new HTTPS connection (1): httpbin.org:443
